2020-08-01 00:18:11,153 -  nornir.core -     INFO -        run() - Running task 'PUSHING NHRP VIA RESTCONF' with args {'name': 'PUSHING NHRP VIA RESTCONF', 'chained_url': 'data/native/interface', 'headers': {'get': {'Accept': 'application/yang-data+json'}, 'put_post': {'Content-Type': 'application/yang-data+json', 'Accept': 'application/yang-data+json, application/yang-data.errors+json'}}} on 3 hosts
2020-08-01 00:18:11,273 - nornir.core.task -    ERROR -      start() - Host 'HUB': task 'RESTCONF PUT_POST' failed with traceback:
Traceback (most recent call last):
  File "/Library/Frameworks/Python.framework/Versions/3.8/lib/python3.8/site-packages/urllib3/connectionpool.py", line 665, in urlopen
    httplib_response = self._make_request(
  File "/Library/Frameworks/Python.framework/Versions/3.8/lib/python3.8/site-packages/urllib3/connectionpool.py", line 376, in _make_request
    self._validate_conn(conn)
  File "/Library/Frameworks/Python.framework/Versions/3.8/lib/python3.8/site-packages/urllib3/connectionpool.py", line 994, in _validate_conn
    conn.connect()
  File "/Library/Frameworks/Python.framework/Versions/3.8/lib/python3.8/site-packages/urllib3/connection.py", line 352, in connect
    self.sock = ssl_wrap_socket(
  File "/Library/Frameworks/Python.framework/Versions/3.8/lib/python3.8/site-packages/urllib3/util/ssl_.py", line 383, in ssl_wrap_socket
    return context.wrap_socket(sock)
  File "/Library/Frameworks/Python.framework/Versions/3.8/lib/python3.8/ssl.py", line 500, in wrap_socket
    return self.sslsocket_class._create(
  File "/Library/Frameworks/Python.framework/Versions/3.8/lib/python3.8/ssl.py", line 1040, in _create
    self.do_handshake()
  File "/Library/Frameworks/Python.framework/Versions/3.8/lib/python3.8/ssl.py", line 1309, in do_handshake
    self._sslobj.do_handshake()
ssl.SSLError: [SSL: TLSV1_ALERT_INTERNAL_ERROR] tlsv1 alert internal error (_ssl.c:1108)

During handling of the above exception, another exception occurred:

Traceback (most recent call last):
  File "/Library/Frameworks/Python.framework/Versions/3.8/lib/python3.8/site-packages/requests/adapters.py", line 439, in send
    resp = conn.urlopen(
  File "/Library/Frameworks/Python.framework/Versions/3.8/lib/python3.8/site-packages/urllib3/connectionpool.py", line 719, in urlopen
    retries = retries.increment(
  File "/Library/Frameworks/Python.framework/Versions/3.8/lib/python3.8/site-packages/urllib3/util/retry.py", line 436, in increment
    raise MaxRetryError(_pool, url, error or ResponseError(cause))
urllib3.exceptions.MaxRetryError: HTTPSConnectionPool(host='192.168.1.216', port=443): Max retries exceeded with url: /restconf/data/native/interface (Caused by SSLError(SSLError(1, '[SSL: TLSV1_ALERT_INTERNAL_ERROR] tlsv1 alert internal error (_ssl.c:1108)')))

During handling of the above exception, another exception occurred:

Traceback (most recent call last):
  File "/Library/Frameworks/Python.framework/Versions/3.8/lib/python3.8/site-packages/nornir/core/task.py", line 85, in start
    r = self.task(self, **self.params)
  File "/Library/Frameworks/Python.framework/Versions/3.8/lib/python3.8/site-packages/nornir/plugins/tasks/apis/http_method.py", line 36, in http_method
    r = requests.request(method, url, **kwargs)
  File "/Library/Frameworks/Python.framework/Versions/3.8/lib/python3.8/site-packages/requests/api.py", line 61, in request
    return session.request(method=method, url=url, **kwargs)
  File "/Library/Frameworks/Python.framework/Versions/3.8/lib/python3.8/site-packages/requests/sessions.py", line 530, in request
    resp = self.send(prep, **send_kwargs)
  File "/Library/Frameworks/Python.framework/Versions/3.8/lib/python3.8/site-packages/requests/sessions.py", line 643, in send
    r = adapter.send(request, **kwargs)
  File "/Library/Frameworks/Python.framework/Versions/3.8/lib/python3.8/site-packages/requests/adapters.py", line 514, in send
    raise SSLError(e, request=request)
requests.exceptions.SSLError: HTTPSConnectionPool(host='192.168.1.216', port=443): Max retries exceeded with url: /restconf/data/native/interface (Caused by SSLError(SSLError(1, '[SSL: TLSV1_ALERT_INTERNAL_ERROR] tlsv1 alert internal error (_ssl.c:1108)')))

2020-08-01 00:18:11,273 - nornir.core.task -    ERROR -      start() - Host 'HUB': task 'PUSHING NHRP VIA RESTCONF' failed with traceback:
Traceback (most recent call last):
  File "/Library/Frameworks/Python.framework/Versions/3.8/lib/python3.8/site-packages/nornir/core/task.py", line 85, in start
    r = self.task(self, **self.params)
  File "nhrp.py", line 10, in nhrpconf
    task.run(
  File "/Library/Frameworks/Python.framework/Versions/3.8/lib/python3.8/site-packages/nornir/core/task.py", line 147, in run
    raise NornirSubTaskError(task=task, result=r)
nornir.core.exceptions.NornirSubTaskError: Subtask: <function http_method at 0x7fdd160e7ee0> (failed)


2020-08-01 00:18:12,201 - nornir.core.task -    ERROR -      start() - Host 'SPOKE1': task 'RESTCONF PUT_POST' failed with traceback:
Traceback (most recent call last):
  File "/Library/Frameworks/Python.framework/Versions/3.8/lib/python3.8/site-packages/urllib3/connectionpool.py", line 665, in urlopen
    httplib_response = self._make_request(
  File "/Library/Frameworks/Python.framework/Versions/3.8/lib/python3.8/site-packages/urllib3/connectionpool.py", line 376, in _make_request
    self._validate_conn(conn)
  File "/Library/Frameworks/Python.framework/Versions/3.8/lib/python3.8/site-packages/urllib3/connectionpool.py", line 994, in _validate_conn
    conn.connect()
  File "/Library/Frameworks/Python.framework/Versions/3.8/lib/python3.8/site-packages/urllib3/connection.py", line 352, in connect
    self.sock = ssl_wrap_socket(
  File "/Library/Frameworks/Python.framework/Versions/3.8/lib/python3.8/site-packages/urllib3/util/ssl_.py", line 383, in ssl_wrap_socket
    return context.wrap_socket(sock)
  File "/Library/Frameworks/Python.framework/Versions/3.8/lib/python3.8/ssl.py", line 500, in wrap_socket
    return self.sslsocket_class._create(
  File "/Library/Frameworks/Python.framework/Versions/3.8/lib/python3.8/ssl.py", line 1040, in _create
    self.do_handshake()
  File "/Library/Frameworks/Python.framework/Versions/3.8/lib/python3.8/ssl.py", line 1309, in do_handshake
    self._sslobj.do_handshake()
ssl.SSLError: [SSL: TLSV1_ALERT_INTERNAL_ERROR] tlsv1 alert internal error (_ssl.c:1108)

During handling of the above exception, another exception occurred:

Traceback (most recent call last):
  File "/Library/Frameworks/Python.framework/Versions/3.8/lib/python3.8/site-packages/requests/adapters.py", line 439, in send
    resp = conn.urlopen(
  File "/Library/Frameworks/Python.framework/Versions/3.8/lib/python3.8/site-packages/urllib3/connectionpool.py", line 719, in urlopen
    retries = retries.increment(
  File "/Library/Frameworks/Python.framework/Versions/3.8/lib/python3.8/site-packages/urllib3/util/retry.py", line 436, in increment
    raise MaxRetryError(_pool, url, error or ResponseError(cause))
urllib3.exceptions.MaxRetryError: HTTPSConnectionPool(host='192.168.1.211', port=443): Max retries exceeded with url: /restconf/data/native/interface (Caused by SSLError(SSLError(1, '[SSL: TLSV1_ALERT_INTERNAL_ERROR] tlsv1 alert internal error (_ssl.c:1108)')))

During handling of the above exception, another exception occurred:

Traceback (most recent call last):
  File "/Library/Frameworks/Python.framework/Versions/3.8/lib/python3.8/site-packages/nornir/core/task.py", line 85, in start
    r = self.task(self, **self.params)
  File "/Library/Frameworks/Python.framework/Versions/3.8/lib/python3.8/site-packages/nornir/plugins/tasks/apis/http_method.py", line 36, in http_method
    r = requests.request(method, url, **kwargs)
  File "/Library/Frameworks/Python.framework/Versions/3.8/lib/python3.8/site-packages/requests/api.py", line 61, in request
    return session.request(method=method, url=url, **kwargs)
  File "/Library/Frameworks/Python.framework/Versions/3.8/lib/python3.8/site-packages/requests/sessions.py", line 530, in request
    resp = self.send(prep, **send_kwargs)
  File "/Library/Frameworks/Python.framework/Versions/3.8/lib/python3.8/site-packages/requests/sessions.py", line 643, in send
    r = adapter.send(request, **kwargs)
  File "/Library/Frameworks/Python.framework/Versions/3.8/lib/python3.8/site-packages/requests/adapters.py", line 514, in send
    raise SSLError(e, request=request)
requests.exceptions.SSLError: HTTPSConnectionPool(host='192.168.1.211', port=443): Max retries exceeded with url: /restconf/data/native/interface (Caused by SSLError(SSLError(1, '[SSL: TLSV1_ALERT_INTERNAL_ERROR] tlsv1 alert internal error (_ssl.c:1108)')))

2020-08-01 00:18:12,202 - nornir.core.task -    ERROR -      start() - Host 'SPOKE1': task 'PUSHING NHRP VIA RESTCONF' failed with traceback:
Traceback (most recent call last):
  File "/Library/Frameworks/Python.framework/Versions/3.8/lib/python3.8/site-packages/nornir/core/task.py", line 85, in start
    r = self.task(self, **self.params)
  File "nhrp.py", line 10, in nhrpconf
    task.run(
  File "/Library/Frameworks/Python.framework/Versions/3.8/lib/python3.8/site-packages/nornir/core/task.py", line 147, in run
    raise NornirSubTaskError(task=task, result=r)
nornir.core.exceptions.NornirSubTaskError: Subtask: <function http_method at 0x7fdd160e7ee0> (failed)


2020-08-01 00:18:44,214 - nornir.core.task -    ERROR -      start() - Host 'SPOKE2': task 'RESTCONF PUT_POST' failed with traceback:
Traceback (most recent call last):
  File "/Library/Frameworks/Python.framework/Versions/3.8/lib/python3.8/site-packages/urllib3/connection.py", line 156, in _new_conn
    conn = connection.create_connection(
  File "/Library/Frameworks/Python.framework/Versions/3.8/lib/python3.8/site-packages/urllib3/util/connection.py", line 84, in create_connection
    raise err
  File "/Library/Frameworks/Python.framework/Versions/3.8/lib/python3.8/site-packages/urllib3/util/connection.py", line 74, in create_connection
    sock.connect(sa)
TimeoutError: [Errno 60] Operation timed out

During handling of the above exception, another exception occurred:

Traceback (most recent call last):
  File "/Library/Frameworks/Python.framework/Versions/3.8/lib/python3.8/site-packages/urllib3/connectionpool.py", line 665, in urlopen
    httplib_response = self._make_request(
  File "/Library/Frameworks/Python.framework/Versions/3.8/lib/python3.8/site-packages/urllib3/connectionpool.py", line 376, in _make_request
    self._validate_conn(conn)
  File "/Library/Frameworks/Python.framework/Versions/3.8/lib/python3.8/site-packages/urllib3/connectionpool.py", line 994, in _validate_conn
    conn.connect()
  File "/Library/Frameworks/Python.framework/Versions/3.8/lib/python3.8/site-packages/urllib3/connection.py", line 300, in connect
    conn = self._new_conn()
  File "/Library/Frameworks/Python.framework/Versions/3.8/lib/python3.8/site-packages/urllib3/connection.py", line 168, in _new_conn
    raise NewConnectionError(
urllib3.exceptions.NewConnectionError: <urllib3.connection.VerifiedHTTPSConnection object at 0x7fdd1618c5e0>: Failed to establish a new connection: [Errno 60] Operation timed out

During handling of the above exception, another exception occurred:

Traceback (most recent call last):
  File "/Library/Frameworks/Python.framework/Versions/3.8/lib/python3.8/site-packages/requests/adapters.py", line 439, in send
    resp = conn.urlopen(
  File "/Library/Frameworks/Python.framework/Versions/3.8/lib/python3.8/site-packages/urllib3/connectionpool.py", line 719, in urlopen
    retries = retries.increment(
  File "/Library/Frameworks/Python.framework/Versions/3.8/lib/python3.8/site-packages/urllib3/util/retry.py", line 436, in increment
    raise MaxRetryError(_pool, url, error or ResponseError(cause))
urllib3.exceptions.MaxRetryError: HTTPSConnectionPool(host='192.168.1.221', port=443): Max retries exceeded with url: /restconf/data/native/interface (Caused by NewConnectionError('<urllib3.connection.VerifiedHTTPSConnection object at 0x7fdd1618c5e0>: Failed to establish a new connection: [Errno 60] Operation timed out'))

During handling of the above exception, another exception occurred:

Traceback (most recent call last):
  File "/Library/Frameworks/Python.framework/Versions/3.8/lib/python3.8/site-packages/nornir/core/task.py", line 85, in start
    r = self.task(self, **self.params)
  File "/Library/Frameworks/Python.framework/Versions/3.8/lib/python3.8/site-packages/nornir/plugins/tasks/apis/http_method.py", line 36, in http_method
    r = requests.request(method, url, **kwargs)
  File "/Library/Frameworks/Python.framework/Versions/3.8/lib/python3.8/site-packages/requests/api.py", line 61, in request
    return session.request(method=method, url=url, **kwargs)
  File "/Library/Frameworks/Python.framework/Versions/3.8/lib/python3.8/site-packages/requests/sessions.py", line 530, in request
    resp = self.send(prep, **send_kwargs)
  File "/Library/Frameworks/Python.framework/Versions/3.8/lib/python3.8/site-packages/requests/sessions.py", line 643, in send
    r = adapter.send(request, **kwargs)
  File "/Library/Frameworks/Python.framework/Versions/3.8/lib/python3.8/site-packages/requests/adapters.py", line 516, in send
    raise ConnectionError(e, request=request)
requests.exceptions.ConnectionError: HTTPSConnectionPool(host='192.168.1.221', port=443): Max retries exceeded with url: /restconf/data/native/interface (Caused by NewConnectionError('<urllib3.connection.VerifiedHTTPSConnection object at 0x7fdd1618c5e0>: Failed to establish a new connection: [Errno 60] Operation timed out'))

2020-08-01 00:18:44,215 - nornir.core.task -    ERROR -      start() - Host 'SPOKE2': task 'PUSHING NHRP VIA RESTCONF' failed with traceback:
Traceback (most recent call last):
  File "/Library/Frameworks/Python.framework/Versions/3.8/lib/python3.8/site-packages/nornir/core/task.py", line 85, in start
    r = self.task(self, **self.params)
  File "nhrp.py", line 10, in nhrpconf
    task.run(
  File "/Library/Frameworks/Python.framework/Versions/3.8/lib/python3.8/site-packages/nornir/core/task.py", line 147, in run
    raise NornirSubTaskError(task=task, result=r)
nornir.core.exceptions.NornirSubTaskError: Subtask: <function http_method at 0x7fdd160e7ee0> (failed)


2020-08-01 00:18:44,215 -  nornir.core -     INFO -        run() - Running task 'PUSHING CRYPTOGRAPHY VIA RESTCONF' with args {'name': 'PUSHING CRYPTOGRAPHY VIA RESTCONF', 'chained_url': 'data/native/crypto', 'headers': {'get': {'Accept': 'application/yang-data+json'}, 'put_post': {'Content-Type': 'application/yang-data+json', 'Accept': 'application/yang-data+json, application/yang-data.errors+json'}}} on 3 hosts
2020-08-01 00:18:44,215 -  nornir.core -     INFO -        run() - Running task 'PUSHING EIGRP VIA RESTCONF' with args {'name': 'PUSHING EIGRP VIA RESTCONF', 'chained_url': 'data/native/router', 'headers': {'get': {'Accept': 'application/yang-data+json'}, 'put_post': {'Content-Type': 'application/yang-data+json', 'Accept': 'application/yang-data+json, application/yang-data.errors+json'}}} on 3 hosts
